Workbook
Name Slicer_اسم_الخط: #N/A
Name Slicer_اسم_السائق: #N/A
Name Slicer_اسم_الشركة: #N/A
Name Slicer_الشهر: #N/A
Name Slicer_كود_السائق: #N/A

Sheet Dashboard

Sheet البداية-قليوب
A1: شركة البدايه الاولى لحلول الاعمال-خط قليوب
A2: م | B2: التاريخ | C2: اسم السائق | D2: خط الدورة | E2: سعر اليومية | F2: اليومية | G2: سلف | H2: خصومات | I2: اضافي | J2: الصافي | K2: ملاحظات
A3: 1 | B3: 46024 | C3: مصطفي | D3: قليوب | E3: 1000 | F3: 1 | J3: =E3*F3-G3-H3+I3 -> 1000 | N3: TO DATE
A4: 2 | B4: 46025 | C4: مصطفي | D4: قليوب | E4: 1000 | J4: =E4*F4-G4-H4+I4 -> 0 | M4: اجمالي الدورة | Q4: =SUM(J3:J367) -> 1000
A5: 3 | B5: 46026 | C5: مصطفي | D5: قليوب | E5: 1000 | J5: =E5*F5-G5-H5+I5 -> 0
A6: 4 | B6: 46027 | C6: مصطفي | D6: قليوب | E6: 1000 | J6: =E6*F6-G6-H6+I6 -> 0
A7: 5 | B7: 46028 | C7: مصطفي | D7: قليوب | E7: 1000 | J7: =E7*F7-G7-H7+I7 -> 0
A8: 6 | B8: 46029 | C8: مصطفي | D8: قليوب | E8: 1000 | J8: =E8*F8-G8-H8+I8 -> 0
A9: 7 | B9: 46030 | C9: مصطفي | D9: قليوب | E9: 1000 | J9: =E9*F9-G9-H9+I9 -> 0
A10: 8 | B10: 46031 | C10: مصطفي | D10: قليوب | E10: 1000 | J10: =E10*F10-G10-H10+I10 -> 0
A11: 9 | B11: 46032 | C11: مصطفي | D11: قليوب | E11: 1000 | J11: =E11*F11-G11-H11+I11 -> 0
A12: 10 | B12: 46033 | C12: مصطفي | D12: قليوب | E12: 1000 | J12: =E12*F12-G12-H12+I12 -> 0
A13: 11 | B13: 46034 | C13: مصطفي | D13: قليوب | E13: 1000 | J13: =E13*F13-G13-H13+I13 -> 0
A14: 12 | B14: 46035 | C14: مصطفي | D14: قليوب | E14: 1000 | J14: =E14*F14-G14-H14+I14 -> 0
A15: 13 | B15: 46036 | C15: مصطفي | D15: قليوب | E15: 1000 | J15: =E15*F15-G15-H15+I15 -> 0
A16: 14 | B16: 46037 | C16: مصطفي | D16: قليوب | E16: 1000 | J16: =E16*F16-G16-H16+I16 -> 0
... A367: 365 | B367: 46388 | C367: مصطفي | D367: قليوب | E367: 1000 | J367: =E367*F367-G367-H367+I367 -> 0

Sheet البداية-داخلي
A1: شركة البدايه الاولى لحلول الاعمال-خط داخلي
A2: م | B2: التاريخ | C2: اسم السائق | D2: خط الدورة | E2: سعر اليومية | F2: اليومية | G2: سلف | H2: خصومات | I2: اضافي | J2: الصافي | K2: ملاحظات
A3: 1 | B3: 46024 | C3: سعيد الصباغ | D3: داخلي | E3: 1136 | F3: 1 | J3: =E3*F3-G3-H3+I3 -> 1136 | O3: TO DATE
A4: 2 | B4: 46025 | C4: سعيد الصباغ | D4: داخلي | E4: 1136 | J4: =E4*F4-G4-H4+I4 -> 0 | N4: اجمالي الدورة | R4: =SUM(J3:J368) -> 1136
A5: 3 | B5: 46026 | C5: سعيد الصباغ | D5: داخلي | E5: 1136 | J5: =E5*F5-G5-H5+I5 -> 0
A6: 4 | B6: 46027 | C6: سعيد الصباغ | D6: داخلي | E6: 1136 | J6: =E6*F6-G6-H6+I6 -> 0
A7: 5 | B7: 46028 | C7: سعيد الصباغ | D7: داخلي | E7: 1136 | J7: =E7*F7-G7-H7+I7 -> 0
A8: 6 | B8: 46029 | C8: سعيد الصباغ | D8: داخلي | E8: 1136 | J8: =E8*F8-G8-H8+I8 -> 0
A9: 7 | B9: 46030 | C9: سعيد الصباغ | D9: داخلي | E9: 1136 | J9: =E9*F9-G9-H9+I9 -> 0
A10: 8 | B10: 46031 | C10: سعيد الصباغ | D10: داخلي | E10: 1136 | J10: =E10*F10-G10-H10+I10 -> 0
A11: 9 | B11: 46032 | C11: سعيد الصباغ | D11: داخلي | E11: 1136 | J11: =E11*F11-G11-H11+I11 -> 0
A12: 10 | B12: 46033 | C12: سعيد الصباغ | D12: داخلي | E12: 1136 | J12: =E12*F12-G12-H12+I12 -> 0
A13: 11 | B13: 46034 | C13: سعيد الصباغ | D13: داخلي | E13: 1136 | J13: =E13*F13-G13-H13+I13 -> 0
A14: 12 | B14: 46035 | C14: سعيد الصباغ | D14: داخلي | E14: 1136 | J14: =E14*F14-G14-H14+I14 -> 0
A15: 13 | B15: 46036 | C15: سعيد الصباغ | D15: داخلي | E15: 1136 | J15: =E15*F15-G15-H15+I15 -> 0
A16: 14 | B16: 46037 | C16: سعيد الصباغ | D16: داخلي | E16: 1136 | J16: =E16*F16-G16-H16+I16 -> 0
... A367: 365 | B367: 46388 | C367: سعيد الصباغ | D367: داخلي | E367: 1136 | J367: =E367*F367-G367-H367+I367 -> 0

Sheet لوجستيك-المرج صباحي
A1: شركة لوجستيكا للخدمات اللوجستية-خط المرج صباحي
A2: م | B2: التاريخ | C2: اسم السائق | D2: خط الدورة | E2: سعر اليومية | F2: اليومية | G2: سلف | H2: خصومات | I2: اضافي | J2: الصافي | K2: ملاحظات
A3: 1 | B3: 46024 | C3: رجب سلامة | D3: المرج -صباحي | E3: 1700 | F3: 1 | J3: =E3*F3-G3-H3+I3 -> 1700 | O3: TO DATE
A4: 2 | B4: 46025 | C4: رجب سلامة | D4: المرج -صباحي | E4: 1700 | J4: =E4*F4-G4-H4+I4 -> 0 | N4: اجمالي الدورة | R4: =SUM(J3:J368) -> 1700
A5: 3 | B5: 46026 | C5: رجب سلامة | D5: المرج -صباحي | E5: 1700 | J5: =E5*F5-G5-H5+I5 -> 0
A6: 4 | B6: 46027 | C6: رجب سلامة | D6: المرج -صباحي | E6: 1700 | J6: =E6*F6-G6-H6+I6 -> 0
A7: 5 | B7: 46028 | C7: رجب سلامة | D7: المرج -صباحي | E7: 1700 | J7: =E7*F7-G7-H7+I7 -> 0
A8: 6 | B8: 46029 | C8: رجب سلامة | D8: المرج -صباحي | E8: 1700 | J8: =E8*F8-G8-H8+I8 -> 0
A9: 7 | B9: 46030 | C9: رجب سلامة | D9: المرج -صباحي | E9: 1700 | J9: =E9*F9-G9-H9+I9 -> 0
A10: 8 | B10: 46031 | C10: رجب سلامة | D10: المرج -صباحي | E10: 1700 | J10: =E10*F10-G10-H10+I10 -> 0
A11: 9 | B11: 46032 | C11: رجب سلامة | D11: المرج -صباحي | E11: 1700 | J11: =E11*F11-G11-H11+I11 -> 0
A12: 10 | B12: 46033 | C12: رجب سلامة | D12: المرج -صباحي | E12: 1700 | J12: =E12*F12-G12-H12+I12 -> 0
A13: 11 | B13: 46034 | C13: رجب سلامة | D13: المرج -صباحي | E13: 1700 | J13: =E13*F13-G13-H13+I13 -> 0
A14: 12 | B14: 46035 | C14: رجب سلامة | D14: المرج -صباحي | E14: 1700 | J14: =E14*F14-G14-H14+I14 -> 0
A15: 13 | B15: 46036 | C15: رجب سلامة | D15: المرج -صباحي | E15: 1700 | J15: =E15*F15-G15-H15+I15 -> 0
A16: 14 | B16: 46037 | C16: رجب سلامة | D16: المرج -صباحي | E16: 1700 | J16: =E16*F16-G16-H16+I16 -> 0
... A367: 365 | B367: 46388 | C367: رجب سلامة | D367: المرج -صباحي | E367: 1700 | J367: =E367*F367-G367-H367+I367 -> 0

Sheet لوجستيك-نكلا م.ذهاب
A1: شركة لوجستيكا للخدمات اللوجستية-خط نكلا القناطر مسائي-ذهاب
A2: م | B2: التاريخ | C2: اسم السائق | D2: خط الدورة | E2: سعر اليومية | F2: اليومية | G2: سلف | H2: خصومات | I2: اضافي | J2: الصافي | K2: ملاحظات
A3: 1 | B3: 46024 | C3: رجب سلامة | D3: نكلا القناطر-م ذهاب | E3: 875 | F3: 1 | J3: =E3*F3-G3-H3+I3 -> 875 | O3: TO DATE
A4: 2 | B4: 46025 | C4: رجب سلامة | D4: نكلا القناطر-م ذهاب | E4: 875 | J4: =E4*F4-G4-H4+I4 -> 0 | N4: اجمالي الدورة | R4: =SUM(J3:J368) -> 875
A5: 3 | B5: 46026 | C5: رجب سلامة | D5: نكلا القناطر-م ذهاب | E5: 875 | J5: =E5*F5-G5-H5+I5 -> 0
A6: 4 | B6: 46027 | C6: رجب سلامة | D6: نكلا القناطر-م ذهاب | E6: 875 | J6: =E6*F6-G6-H6+I6 -> 0
A7: 5 | B7: 46028 | C7: رجب سلامة | D7: نكلا القناطر-م ذهاب | E7: 875 | J7: =E7*F7-G7-H7+I7 -> 0
A8: 6 | B8: 46029 | C8: رجب سلامة | D8: نكلا القناطر-م ذهاب | E8: 875 | J8: =E8*F8-G8-H8+I8 -> 0
A9: 7 | B9: 46030 | C9: رجب سلامة | D9: نكلا القناطر-م ذهاب | E9: 875 | J9: =E9*F9-G9-H9+I9 -> 0
A10: 8 | B10: 46031 | C10: رجب سلامة | D10: نكلا القناطر-م ذهاب | E10: 875 | J10: =E10*F10-G10-H10+I10 -> 0
A11: 9 | B11: 46032 | C11: رجب سلامة | D11: نكلا القناطر-م ذهاب | E11: 875 | J11: =E11*F11-G11-H11+I11 -> 0
A12: 10 | B12: 46033 | C12: رجب سلامة | D12: نكلا القناطر-م ذهاب | E12: 875 | J12: =E12*F12-G12-H12+I12 -> 0
A13: 11 | B13: 46034 | C13: رجب سلامة | D13: نكلا القناطر-م ذهاب | E13: 875 | J13: =E13*F13-G13-H13+I13 -> 0
A14: 12 | B14: 46035 | C14: رجب سلامة | D14: نكلا القناطر-م ذهاب | E14: 875 | J14: =E14*F14-G14-H14+I14 -> 0
A15: 13 | B15: 46036 | C15: رجب سلامة | D15: نكلا القناطر-م ذهاب | E15: 875 | J15: =E15*F15-G15-H15+I15 -> 0
A16: 14 | B16: 46037 | C16: رجب سلامة | D16: نكلا القناطر-م ذهاب | E16: 875 | J16: =E16*F16-G16-H16+I16 -> 0
... A367: 365 | B367: 46388 | C367: رجب سلامة | D367: نكلا القناطر-م ذهاب | E367: 875 | J367: =E367*F367-G367-H367+I367 -> 0

Sheet لوجستيك-حدائق-الادارة
A1: شركة لوجستيكا للخدمات اللوجستية-خط حدائق الاهرام -الادارة
A2: م | B2: التاريخ | C2: اسم السائق | D2: خط الدورة | E2: سعر اليومية | F2: اليومية | G2: سلف | H2: خصومات | I2: اضافي | J2: الصافي | K2: ملاحظات | O2: TO DATE
A3: 1 | B3: 46024 | C3: محمد عزمي | D3: حدائق الاهرام-الادارة | E3: 1450 | F3: 1 | J3: =E3*F3-G3-H3+I3 -> 1450 | N3: اجمالي الدورة | R3: =SUM(J2:J367) -> 1450
A4: 2 | B4: 46025 | C4: محمد عزمي | D4: حدائق الاهرام-الادارة | E4: 1450 | J4: =E4*F4-G4-H4+I4 -> 0
A5: 3 | B5: 46026 | C5: محمد عزمي | D5: حدائق الاهرام-الادارة | E5: 1450 | J5: =E5*F5-G5-H5+I5 -> 0
A6: 4 | B6: 46027 | C6: محمد عزمي | D6: حدائق الاهرام-الادارة | E6: 1450 | J6: =E6*F6-G6-H6+I6 -> 0
A7: 5 | B7: 46028 | C7: محمد عزمي | D7: حدائق الاهرام-الادارة | E7: 1450 | J7: =E7*F7-G7-H7+I7 -> 0
A8: 6 | B8: 46029 | C8: محمد عزمي | D8: حدائق الاهرام-الادارة | E8: 1450 | J8: =E8*F8-G8-H8+I8 -> 0
A9: 7 | B9: 46030 | C9: محمد عزمي | D9: حدائق الاهرام-الادارة | E9: 1450 | J9: =E9*F9-G9-H9+I9 -> 0
A10: 8 | B10: 46031 | C10: محمد عزمي | D10: حدائق الاهرام-الادارة | E10: 1450 | J10: =E10*F10-G10-H10+I10 -> 0
A11: 9 | B11: 46032 | C11: محمد عزمي | D11: حدائق الاهرام-الادارة | E11: 1450 | J11: =E11*F11-G11-H11+I11 -> 0
A12: 10 | B12: 46033 | C12: محمد عزمي | D12: حدائق الاهرام-الادارة | E12: 1450 | J12: =E12*F12-G12-H12+I12 -> 0
A13: 11 | B13: 46034 | C13: محمد عزمي | D13: حدائق الاهرام-الادارة | E13: 1450 | J13: =E13*F13-G13-H13+I13 -> 0
A14: 12 | B14: 46035 | C14: محمد عزمي | D14: حدائق الاهرام-الادارة | E14: 1450 | J14: =E14*F14-G14-H14+I14 -> 0
A15: 13 | B15: 46036 | C15: محمد عزمي | D15: حدائق الاهرام-الادارة | E15: 1450 | J15: =E15*F15-G15-H15+I15 -> 0
... A367: 365 | B367: 46388 | C367: محمد عزمي | D367: حدائق الاهرام-الادارة | E367: 1450 | J367: =E367*F367-G367-H367+I367 -> 0

Sheet لوجستيك-منوفية-صباحي
A1: شركة لوجستيكا للخدمات اللوجستية-خط المنوفية-صباحي
A2: م | B2: التاريخ | C2: اسم السائق | D2: خط الدورة | E2: سعر اليومية | F2: اليومية | G2: سلف | H2: خصومات | I2: اضافي | J2: الصافي | K2: ملاحظات
A3: 1 | B3: 46024 | C3: محمد رضا | D3: المنوفية-صباحي | E3: 1850 | F3: 1 | J3: =E3*F3-G3-H3+I3 -> 1850 | N3: TO DATE
A4: 2 | B4: 46025 | C4: محمد رضا | D4: المنوفية-صباحي | E4: 1850 | J4: =E4*F4-G4-H4+I4 -> 0 | M4: اجمالي الدورة | Q4: =SUM(J3:J367) -> 1850
A5: 3 | B5: 46026 | C5: محمد رضا | D5: المنوفية-صباحي | E5: 1850 | J5: =E5*F5-G5-H5+I5 -> 0
A6: 4 | B6: 46027 | C6: محمد رضا | D6: المنوفية-صباحي | E6: 1850 | J6: =E6*F6-G6-H6+I6 -> 0
A7: 5 | B7: 46028 | C7: محمد رضا | D7: المنوفية-صباحي | E7: 1850 | J7: =E7*F7-G7-H7+I7 -> 0
A8: 6 | B8: 46029 | C8: محمد رضا | D8: المنوفية-صباحي | E8: 1850 | J8: =E8*F8-G8-H8+I8 -> 0
A9: 7 | B9: 46030 | C9: محمد رضا | D9: المنوفية-صباحي | E9: 1850 | J9: =E9*F9-G9-H9+I9 -> 0
A10: 8 | B10: 46031 | C10: محمد رضا | D10: المنوفية-صباحي | E10: 1850 | J10: =E10*F10-G10-H10+I10 -> 0
A11: 9 | B11: 46032 | C11: محمد رضا | D11: المنوفية-صباحي | E11: 1850 | J11: =E11*F11-G11-H11+I11 -> 0
A12: 10 | B12: 46033 | C12: محمد رضا | D12: المنوفية-صباحي | E12: 1850 | J12: =E12*F12-G12-H12+I12 -> 0
A13: 11 | B13: 46034 | C13: محمد رضا | D13: المنوفية-صباحي | E13: 1850 | J13: =E13*F13-G13-H13+I13 -> 0
A14: 12 | B14: 46035 | C14: محمد رضا | D14: المنوفية-صباحي | E14: 1850 | J14: =E14*F14-G14-H14+I14 -> 0
A15: 13 | B15: 46036 | C15: محمد رضا | D15: المنوفية-صباحي | E15: 1850 | J15: =E15*F15-G15-H15+I15 -> 0
A16: 14 | B16: 46037 | C16: محمد رضا | D16: المنوفية-صباحي | E16: 1850 | J16: =E16*F16-G16-H16+I16 -> 0
... A367: 365 | B367: 46388 | C367: محمد رضا | D367: المنوفية-صباحي | E367: 1850 | J367: =E367*F367-G367-H367+I367 -> 0

Sheet Sheet1
X7: 140350.88 | Y7: 112000 | Z7: 112000
X8: 140350.88 | Y8: 99076.92
X9: 122807.02 | Y9: 112000
Y10: 112000
Y11: 112000
Y12: 112000
X18: =SUM(X7:X16) -> 403508.78 | Y18: =SUM(Y7:Y15) -> 659076.92 | Z18: =SUM(Z7:Z14) -> 112000

Sheet لوجستيك-مخزن عفيفي
A1: شركة لوجستيكا للخدمات اللوجستية-خط مخزن عفيفي
A2: م | B2: التاريخ | C2: اسم السائق | D2: خط الدورة | E2: سعر اليومية | F2: اليومية | G2: سلف | H2: خصومات | I2: اضافي | J2: الصافي | K2: ملاحظات
A3: 1 | B3: 46024 | C3: محمد رضا | D3: مخزن عفيفي | E3: 100 | F3: 1 | J3: =E3*F3-G3-H3+I3 -> 100
A4: 2 | B4: 46025 | C4: محمد رضا | D4: مخزن عفيفي | E4: 100 | J4: =E4*F4-G4-H4+I4 -> 0
A5: 3 | B5: 46026 | C5: محمد رضا | D5: مخزن عفيفي | E5: 100 | J5: =E5*F5-G5-H5+I5 -> 0 | N5: TO DATE
A6: 4 | B6: 46027 | C6: محمد رضا | D6: مخزن عفيفي | E6: 100 | J6: =E6*F6-G6-H6+I6 -> 0 | M6: اجمالي الدورة | Q6: =SUM(J3:J369) -> 100
A7: 5 | B7: 46028 | C7: محمد رضا | D7: مخزن عفيفي | E7: 100 | J7: =E7*F7-G7-H7+I7 -> 0
A8: 6 | B8: 46029 | C8: محمد رضا | D8: مخزن عفيفي | E8: 100 | J8: =E8*F8-G8-H8+I8 -> 0
A9: 7 | B9: 46030 | C9: محمد رضا | D9: مخزن عفيفي | E9: 100 | J9: =E9*F9-G9-H9+I9 -> 0
A10: 8 | B10: 46031 | C10: محمد رضا | D10: مخزن عفيفي | E10: 100 | J10: =E10*F10-G10-H10+I10 -> 0
A11: 9 | B11: 46032 | C11: محمد رضا | D11: مخزن عفيفي | E11: 100 | J11: =E11*F11-G11-H11+I11 -> 0
A12: 10 | B12: 46033 | C12: محمد رضا | D12: مخزن عفيفي | E12: 100 | J12: =E12*F12-G12-H12+I12 -> 0
A13: 11 | B13: 46034 | C13: محمد رضا | D13: مخزن عفيفي | E13: 100 | J13: =E13*F13-G13-H13+I13 -> 0
A14: 12 | B14: 46035 | C14: محمد رضا | D14: مخزن عفيفي | E14: 100 | J14: =E14*F14-G14-H14+I14 -> 0
A15: 13 | B15: 46036 | C15: محمد رضا | D15: مخزن عفيفي | E15: 100 | J15: =E15*F15-G15-H15+I15 -> 0
A16: 14 | B16: 46037 | C16: محمد رضا | D16: مخزن عفيفي | E16: 100 | J16: =E16*F16-G16-H16+I16 -> 0
A17: 15 | B17: 46038 | C17: محمد رضا | D17: مخزن عفيفي | E17: 100 | J17: =E17*F17-G17-H17+I17 -> 0
A18: 16 | B18: 46039 | C18: محمد رضا | D18: مخزن عفيفي | E18: 100 | J18: =E18*F18-G18-H18+I18 -> 0
... A367: 365 | B367: 46388 | C367: محمد رضا | D367: مخزن عفيفي | E367: 100 | J367: =E367*F367-G367-H367+I367 -> 0

Sheet لوجستيك-نكلا م.عودة
A1: شركة لوجستيكا للخدمات اللوجستية-خط نكلا القناطر مسائي-عودة
A2: م | B2: التاريخ | C2: اسم السائق | D2: خط الدورة | E2: سعر اليومية | F2: اليومية | G2: سلف | H2: خصومات | I2: اضافي | J2: الصافي | K2: ملاحظات
A3: 1 | B3: 46024 | C3: حسام سعيد | D3: نكلا القناطر-م عودة | E3: 800 | F3: 1 | J3: =E3*F3-G3-H3+I3 -> 800
A4: 2 | B4: 46025 | C4: حسام سعيد | D4: نكلا القناطر-م عودة | E4: 800 | J4: =E4*F4-G4-H4+I4 -> 0 | N4: TO DATE
A5: 3 | B5: 46026 | C5: حسام سعيد | D5: نكلا القناطر-م عودة | E5: 800 | J5: =E5*F5-G5-H5+I5 -> 0 | M5: اجمالي الدورة | Q5: =SUM(J2:J368) -> 800
A6: 4 | B6: 46027 | C6: حسام سعيد | D6: نكلا القناطر-م عودة | E6: 800 | J6: =E6*F6-G6-H6+I6 -> 0
A7: 5 | B7: 46028 | C7: حسام سعيد | D7: نكلا القناطر-م عودة | E7: 800 | J7: =E7*F7-G7-H7+I7 -> 0
A8: 6 | B8: 46029 | C8: حسام سعيد | D8: نكلا القناطر-م عودة | E8: 800 | J8: =E8*F8-G8-H8+I8 -> 0
A9: 7 | B9: 46030 | C9: حسام سعيد | D9: نكلا القناطر-م عودة | E9: 800 | J9: =E9*F9-G9-H9+I9 -> 0
A10: 8 | B10: 46031 | C10: حسام سعيد | D10: نكلا القناطر-م عودة | E10: 800 | J10: =E10*F10-G10-H10+I10 -> 0
A11: 9 | B11: 46032 | C11: حسام سعيد | D11: نكلا القناطر-م عودة | E11: 800 | J11: =E11*F11-G11-H11+I11 -> 0
A12: 10 | B12: 46033 | C12: حسام سعيد | D12: نكلا القناطر-م عودة | E12: 800 | J12: =E12*F12-G12-H12+I12 -> 0
A13: 11 | B13: 46034 | C13: حسام سعيد | D13: نكلا القناطر-م عودة | E13: 800 | J13: =E13*F13-G13-H13+I13 -> 0
A14: 12 | B14: 46035 | C14: حسام سعيد | D14: نكلا القناطر-م عودة | E14: 800 | J14: =E14*F14-G14-H14+I14 -> 0
A15: 13 | B15: 46036 | C15: حسام سعيد | D15: نكلا القناطر-م عودة | E15: 800 | J15: =E15*F15-G15-H15+I15 -> 0
A16: 14 | B16: 46037 | C16: حسام سعيد | D16: نكلا القناطر-م عودة | E16: 800 | J16: =E16*F16-G16-H16+I16 -> 0
A17: 15 | B17: 46038 | C17: حسام سعيد | D17: نكلا القناطر-م عودة | E17: 800 | J17: =E17*F17-G17-H17+I17 -> 0
... A367: 365 | B367: 46388 | C367: حسام سعيد | D367: نكلا القناطر-م عودة | E367: 800 | J367: =E367*F367-G367-H367+I367 -> 0

Sheet لوجستيك-القناطر اولي
A1: شركة لوجستيكا للخدمات اللوجستية-خط نكلا القناطر أولي
A2: م | B2: التاريخ | C2: اسم السائق | D2: خط الدورة | E2: سعر اليومية | F2: اليومية | G2: سلف | H2: خصومات | I2: اضافي | J2: الصافي | K2: ملاحظات
A3: 1 | B3: 46024 | C3: حسام سعيد | D3: القناطر اولي | E3: 1055 | F3: 1 | J3: =E3*F3-G3-H3+I3 -> 1055
A4: 2 | B4: 46025 | C4: حسام سعيد | D4: القناطر اولي | E4: 1055 | J4: =E4*F4-G4-H4+I4 -> 0 | N4: TO DATE
A5: 3 | B5: 46026 | C5: حسام سعيد | D5: القناطر اولي | E5: 1055 | J5: =E5*F5-G5-H5+I5 -> 0 | M5: اجمالي الدورة | Q5: =SUM(J2:J368) -> 1055
A6: 4 | B6: 46027 | C6: حسام سعيد | D6: القناطر اولي | E6: 1055 | J6: =E6*F6-G6-H6+I6 -> 0
A7: 5 | B7: 46028 | C7: حسام سعيد | D7: القناطر اولي | E7: 1055 | J7: =E7*F7-G7-H7+I7 -> 0
A8: 6 | B8: 46029 | C8: حسام سعيد | D8: القناطر اولي | E8: 1055 | J8: =E8*F8-G8-H8+I8 -> 0
A9: 7 | B9: 46030 | C9: حسام سعيد | D9: القناطر اولي | E9: 1055 | J9: =E9*F9-G9-H9+I9 -> 0
A10: 8 | B10: 46031 | C10: حسام سعيد | D10: القناطر اولي | E10: 1055 | J10: =E10*F10-G10-H10+I10 -> 0
A11: 9 | B11: 46032 | C11: حسام سعيد | D11: القناطر اولي | E11: 1055 | J11: =E11*F11-G11-H11+I11 -> 0
A12: 10 | B12: 46033 | C12: حسام سعيد | D12: القناطر اولي | E12: 1055 | J12: =E12*F12-G12-H12+I12 -> 0
A13: 11 | B13: 46034 | C13: حسام سعيد | D13: القناطر اولي | E13: 1055 | J13: =E13*F13-G13-H13+I13 -> 0
A14: 12 | B14: 46035 | C14: حسام سعيد | D14: القناطر اولي | E14: 1055 | J14: =E14*F14-G14-H14+I14 -> 0
A15: 13 | B15: 46036 | C15: حسام سعيد | D15: القناطر اولي | E15: 1055 | J15: =E15*F15-G15-H15+I15 -> 0
A16: 14 | B16: 46037 | C16: حسام سعيد | D16: القناطر اولي | E16: 1055 | J16: =E16*F16-G16-H16+I16 -> 0
A17: 15 | B17: 46038 | C17: حسام سعيد | D17: القناطر اولي | E17: 1055 | J17: =E17*F17-G17-H17+I17 -> 0
... A367: 365 | B367: 46388 | C367: حسام سعيد | D367: القناطر اولي | E367: 1055 | J367: =E367*F367-G367-H367+I367 -> 0

Sheet لوجستيك-القناطر ثانية
A1: شركة لوجستيكا للخدمات اللوجستية-خط نكلا القناطر ثانية
A2: م | B2: التاريخ | C2: اسم السائق | D2: خط الدورة | E2: سعر اليومية | F2: اليومية | G2: سلف | H2: خصومات | I2: اضافي | J2: الصافي | K2: ملاحظات
A3: 1 | B3: 46024 | C3: حسام سعيد | D3: القناطر ثانية | E3: 1000 | F3: 1 | J3: =E3*F3-G3-H3+I3 -> 1000
A4: 2 | B4: 46025 | C4: حسام سعيد | D4: القناطر ثانية | E4: 1000 | J4: =E4*F4-G4-H4+I4 -> 0 | N4: TO DATE
A5: 3 | B5: 46026 | C5: حسام سعيد | D5: القناطر ثانية | E5: 1000 | J5: =E5*F5-G5-H5+I5 -> 0 | M5: اجمالي الدورة | Q5: =SUM(J2:J368) -> 1000
A6: 4 | B6: 46027 | C6: حسام سعيد | D6: القناطر ثانية | E6: 1000 | J6: =E6*F6-G6-H6+I6 -> 0
A7: 5 | B7: 46028 | C7: حسام سعيد | D7: القناطر ثانية | E7: 1000 | J7: =E7*F7-G7-H7+I7 -> 0
A8: 6 | B8: 46029 | C8: حسام سعيد | D8: القناطر ثانية | E8: 1000 | J8: =E8*F8-G8-H8+I8 -> 0
A9: 7 | B9: 46030 | C9: حسام سعيد | D9: القناطر ثانية | E9: 1000 | J9: =E9*F9-G9-H9+I9 -> 0
A10: 8 | B10: 46031 | C10: حسام سعيد | D10: القناطر ثانية | E10: 1000 | J10: =E10*F10-G10-H10+I10 -> 0
A11: 9 | B11: 46032 | C11: حسام سعيد | D11: القناطر ثانية | E11: 1000 | J11: =E11*F11-G11-H11+I11 -> 0
A12: 10 | B12: 46033 | C12: حسام سعيد | D12: القناطر ثانية | E12: 1000 | J12: =E12*F12-G12-H12+I12 -> 0
A13: 11 | B13: 46034 | C13: حسام سعيد | D13: القناطر ثانية | E13: 1000 | J13: =E13*F13-G13-H13+I13 -> 0
A14: 12 | B14: 46035 | C14: حسام سعيد | D14: القناطر ثانية | E14: 1000 | J14: =E14*F14-G14-H14+I14 -> 0
A15: 13 | B15: 46036 | C15: حسام سعيد | D15: القناطر ثانية | E15: 1000 | J15: =E15*F15-G15-H15+I15 -> 0
A16: 14 | B16: 46037 | C16: حسام سعيد | D16: القناطر ثانية | E16: 1000 | J16: =E16*F16-G16-H16+I16 -> 0
A17: 15 | B17: 46038 | C17: حسام سعيد | D17: القناطر ثانية | E17: 1000 | J17: =E17*F17-G17-H17+I17 -> 0
... A367: 365 | B367: 46388 | C367: حسام سعيد | D367: القناطر ثانية | E367: 1000 | J367: =E367*F367-G367-H367+I367 -> 0

Sheet mapping
K1: 10 | L1: 3 | M1: 2026 | N1: =K1&L1&M1 -> 1032026
A2: Column1 | B2: Column2 | C2: كود السائق | D2: اسم السائق | E2: اسم الخط | F2: اسم الشركة | G2: الفرع | H2: نوع السيارة | I2: اجمالي سعر اليومية | J2: سعر يومية السائق | K2: سعر اليومية جديد | L2: سعر السائق جديد | M2: التاريخ
A3: =mapping!$D3&mapping!$E3&mapping!$F3&mapping!$G3&mapping!$H3 -> محمد خطاب المنيب 2 ورديةسعوديالقطاميةاتوبيس 28 | B3: =mapping!$D3&mapping!$E3 -> محمد خطاب المنيب 2 وردية | C3: 5016 | D3: محمد خطاب | E3: المنيب 2 وردية | F3: سعودي | G3: القطامية | H3: اتوبيس 28 | I3: 3587 | J3: 3210 | K3: 3959 | L3: 3435
A4: =mapping!$D4&mapping!$E4&mapping!$F4&mapping!$G4&mapping!$H4 -> مصطفي رشدي2المنيب 1 ورديةسعوديميفيداميكروباص صيني | B4: =mapping!$D4&mapping!$E4 -> مصطفي رشدي2المنيب 1 وردية | C4: 5008 | D4: مصطفي رشدي2 | E4: المنيب 1 وردية | F4: سعودي | G4: ميفيدا | H4: ميكروباص صيني | I4: 1348 | J4: 1050 | K4: 1483 | L4: 1150
A5: =mapping!$D5&mapping!$E5&mapping!$F5&mapping!$G5&mapping!$H5 -> عماد النجار 3الدائري 1ورديةسعوديالمخاذناتوبيس 28 | B5: =mapping!$D5&mapping!$E5 -> عماد النجار 3الدائري 1وردية | C5: 5002 | D5: عماد النجار 3 | E5: الدائري 1وردية | F5: سعودي | G5: المخاذن | H5: اتوبيس 28 | I5: 2229 | J5: 2150 | K5: 2448 | L5: 2500
A6: =mapping!$D6&mapping!$E6&mapping!$F6&mapping!$G6&mapping!$H6 -> ايمن الفقيالدائري 1ورديةسعوديالمخاذناتوبيس 28 | B6: =mapping!$D6&mapping!$E6 -> ايمن الفقيالدائري 1وردية | C6: 5031 | D6: ايمن الفقي | E6: الدائري 1وردية | F6: سعودي | G6: المخاذن | H6: اتوبيس 28 | K6: 2448 | L6: 2650
A7: =mapping!$D7&mapping!$E7&mapping!$F7&mapping!$G7&mapping!$H7 -> محمد عبد المنعم قليوب 1 ورديةنجمة هليوبوليسالتجمع اتوبيس 28 | B7: =mapping!$D7&mapping!$E7 -> محمد عبد المنعم قليوب 1 وردية | C7: 3001 | D7: محمد عبد المنعم | E7: قليوب 1 وردية | F7: نجمة هليوبوليس | G7: التجمع | H7: اتوبيس 28 | I7: 1786 | J7: 1800 | K7: 1964 | L7: 2000
A8: =mapping!$D8&mapping!$E8&mapping!$F8&mapping!$G8&mapping!$H8 -> ممدوح كيلاني2المنيب 3وردية نجمة هليوبوليسالتجمع اتوبيس 28 | B8: =mapping!$D8&mapping!$E8 -> ممدوح كيلاني2المنيب 3وردية | C8: 3003 | D8: ممدوح كيلاني2 | E8: المنيب 3وردية | F8: نجمة هليوبوليس | G8: التجمع | H8: اتوبيس 28 | I8: 4016 | J8: 3400 | K8: 4417 | L8: 3700
A9: =mapping!$D9&mapping!$E9&mapping!$F9&mapping!$G9&mapping!$H9 -> وديع 1الفيوم 1لوجستيكااكتوبر هاي اس | B9: =mapping!$D9&mapping!$E9 -> وديع 1الفيوم 1 | C9: 4009 | D9: وديع 1 | E9: الفيوم 1 | F9: لوجستيكا | G9: اكتوبر | H9: هاي اس | I9: 2420 | J9: 2050 | K9: 2662 | L9: 2250
A10: =mapping!$D10&mapping!$E10&mapping!$F10&mapping!$G10&mapping!$H10 -> وديع 2الفيوم 2لوجستيكااكتوبر هاي اس | B10: =mapping!$D10&mapping!$E10 -> وديع 2الفيوم 2 | C10: 4010 | D10: وديع 2 | E10: الفيوم 2 | F10: لوجستيكا | G10: اكتوبر | H10: هاي اس | I10: 2420 | J10: 2050 | K10: 2662 | L10: 2250
A11: =mapping!$D11&mapping!$E11&mapping!$F11&mapping!$G11&mapping!$H11 -> سعيد الصباغ داخلي FIRST STARTالتجمع سوزوكي | B11: =mapping!$D11&mapping!$E11 -> سعيد الصباغ داخلي | C11: 1001 | D11: سعيد الصباغ | E11: داخلي | F11: FIRST START | G11: التجمع | H11: سوزوكي | I11: 30000 | J11: 25000 | K11: 30000 | L11: 25500
A12: =mapping!$D12&mapping!$E12&mapping!$F12&mapping!$G12&mapping!$H12 -> مصطفي قليوبقليوب FIRST STARTم.نصر ميكروباص صيني | B12: =mapping!$D12&mapping!$E12 -> مصطفي قليوبقليوب | C12: 1000 | D12: مصطفي قليوب | E12: قليوب | F12: FIRST START | G12: م.نصر | H12: ميكروباص صيني | I12: 1250 | J12: 1100 | K12: 1250 | L12: 1200
A13: =mapping!$D13&mapping!$E13&mapping!$F13&mapping!$G13&mapping!$H13 -> عمرو برعي الجراجFLITCH AND GRAINالتجمع ميكروباص صيني | B13: =mapping!$D13&mapping!$E13 -> عمرو برعي الجراج | C13: 2000 | D13: عمرو برعي | E13: الجراج | F13: FLITCH AND GRAIN | G13: التجمع | H13: ميكروباص صيني | I13: 1150 | J13: 950 | K13: 1300 | L13: 1050
A14: =mapping!$D14&mapping!$E14&mapping!$F14&mapping!$G14&mapping!$H14 -> مصطفي الف مسكنالف مسكن 3 ورديةنجمة هليوبوليسالتجمع اتوبيس 28 | B14: =mapping!$D14&mapping!$E14 -> مصطفي الف مسكنالف مسكن 3 وردية | C14: 3000 | D14: مصطفي الف مسكن | E14: الف مسكن 3 وردية | F14: نجمة هليوبوليس | G14: التجمع | H14: اتوبيس 28 | I14: 4016 | J14: 3500 | K14: 4297 | L14: 3800
A15: =mapping!$D15&mapping!$E15&mapping!$F15&mapping!$G15&mapping!$H15 -> ممدوح كيلاني1قليوب 3 وردية نجمة هليوبوليسالتجمع اتوبيس 28 | B15: =mapping!$D15&mapping!$E15 -> ممدوح كيلاني1قليوب 3 وردية | C15: 3002 | D15: ممدوح كيلاني1 | E15: قليوب 3 وردية | F15: نجمة هليوبوليس | G15: التجمع | H15: اتوبيس 28 | I15: 4016 | J15: 3600 | K15: 4297 | L15: 3900
A16: =mapping!$D16&mapping!$E16&mapping!$F16&mapping!$G16&mapping!$H16 -> ممدوح كيلاني3المنيب 3وردية نجمة هليوبوليسالتجمع ميكروباص | B16: =mapping!$D16&mapping!$E16 -> ممدوح كيلاني3المنيب 3وردية | C16: 3004 | D16: ممدوح كيلاني3 | E16: المنيب 3وردية | F16: نجمة هليوبوليس | G16: التجمع | H16: ميكروباص | K16: 3600 | L16: 2700
A17: =mapping!$D17&mapping!$E17&mapping!$F17&mapping!$G17&mapping!$H17 -> بكرقليوب 1 ورديةنجمة هليوبوليسالتجمع ميكروباص | B17: =mapping!$D17&mapping!$E17 -> بكرقليوب 1 وردية | C17: 3005 | D17: بكر | E17: قليوب 1 وردية | F17: نجمة هليوبوليس | G17: التجمع | H17: ميكروباص | K17: 1400 | L17: 1200
A18: =mapping!$D18&mapping!$E18&mapping!$F18&mapping!$G18&mapping!$H18 -> رجب سلامة 1المرج لوجستيكااكتوبر هاي اس | B18: =mapping!$D18&mapping!$E18 -> رجب سلامة 1المرج | C18: 4000 | D18: رجب سلامة 1 | E18: المرج | F18: لوجستيكا | G18: اكتوبر | H18: هاي اس | I18: 1996 | J18: 1800 | K18: 2195 | L18: 2000
A19: =mapping!$D19&mapping!$E19&mapping!$F19&mapping!$G19&mapping!$H19 -> رجب سلامة 2 نكلا حضورلوجستيكااكتوبر هاي اس | B19: =mapping!$D19&mapping!$E19 -> رجب سلامة 2 نكلا حضور | C19: 4004 | D19: رجب سلامة 2 | E19: نكلا حضور | F19: لوجستيكا | G19: اكتوبر | H19: هاي اس | I19: 931.5 | J19: 875 | K19: 1024 | L19: 1000
A20: =mapping!$D20&mapping!$E20&mapping!$F20&mapping!$G20&mapping!$H20 -> احمد السيدالمنيب 3وردية لوجستيكااكتوبر هاي اس | B20: =mapping!$D20&mapping!$E20 -> احمد السيدالمنيب 3وردية | C20: 4001 | D20: احمد السيد | E20: المنيب 3وردية | F20: لوجستيكا | G20: اكتوبر | H20: هاي اس | I20: 4392 | J20: 3750 | K20: 4831 | L20: 4000
A21: =mapping!$D21&mapping!$E21&mapping!$F21&mapping!$G21&mapping!$H21 -> حسام سعيد1القناطر 3 ورديةلوجستيكااكتوبر هاي اس | B21: =mapping!$D21&mapping!$E21 -> حسام سعيد1القناطر 3 وردية | C21: 4002 | D21: حسام سعيد1 | E21: القناطر 3 وردية | F21: لوجستيكا | G21: اكتوبر | H21: هاي اس | I21: 3992 | J21: 3100 | K21: 4391 | L21: 3400
A22: =mapping!$D22&mapping!$E22&mapping!$F22&mapping!$G22&mapping!$H22 -> حسام سعيد 2نكلا انصرافلوجستيكااكتوبر هاي اس | B22: =mapping!$D22&mapping!$E22 -> حسام سعيد 2نكلا انصراف | C22: 4003 | D22: حسام سعيد 2 | E22: نكلا انصراف | F22: لوجستيكا | G22: اكتوبر | H22: هاي اس | I22: 931.5 | J22: 800 | K22: 1024 | L22: 900
A23: =mapping!$D23&mapping!$E23&mapping!$F23&mapping!$G23&mapping!$H23 -> محمد رضا المنوفية لوجستيكااكتوبر هاي اس | B23: =mapping!$D23&mapping!$E23 -> محمد رضا المنوفية | C23: 4006 | D23: محمد رضا | E23: المنوفية | F23: لوجستيكا | G23: اكتوبر | H23: هاي اس | I23: 2395 | J23: 1950 | K23: 2634 | L23: 2150
A24: =mapping!$D24&mapping!$E24&mapping!$F24&mapping!$G24&mapping!$H24 -> مصطفي شكيويالجلاتمةلوجستيكااكتوبر كوستر | B24: =mapping!$D24&mapping!$E24 -> مصطفي شكيويالجلاتمة | C24: 4007 | D24: مصطفي شكيوي | E24: الجلاتمة | F24: لوجستيكا | G24: اكتوبر | H24: كوستر | I24: 2928 | J24: 2500 | K24: 3220 | L24: 2750
A25: =mapping!$D25&mapping!$E25&mapping!$F25&mapping!$G25&mapping!$H25 -> وديع 3الفيوم سنهورلوجستيكااكتوبر هاي اس | B25: =mapping!$D25&mapping!$E25 -> وديع 3الفيوم سنهور | C25: 4023 | D25: وديع 3 | E25: الفيوم سنهور | F25: لوجستيكا | G25: اكتوبر | H25: هاي اس | K25: 3000 | L25: 2250
A26: =mapping!$D26&mapping!$E26&mapping!$F26&mapping!$G26&mapping!$H26 -> محمودالعياطلوجستيكااكتوبر هاي اس | B26: =mapping!$D26&mapping!$E26 -> محمودالعياط | C26: 4024 | D26: محمود | E26: العياط | F26: لوجستيكا | G26: اكتوبر | H26: هاي اس | K26: 4000 | L26: 2500
A27: =mapping!$D27&mapping!$E27&mapping!$F27&mapping!$G27&mapping!$H27 -> احمد عويس المعادي لوجستيكاابورواش هاي اس | B27: =mapping!$D27&mapping!$E27 -> احمد عويس المعادي | C27: 4011 | D27: احمد عويس | E27: المعادي | F27: لوجستيكا | G27: ابورواش | H27: هاي اس | I27: 1863 | J27: 1400 | K27: 2049 | L27: 1650
A28: =mapping!$D28&mapping!$E28&mapping!$F28&mapping!$G28&mapping!$H28 -> محمد جمال القناطر لوجستيكاابورواش سوزوكي | B28: =mapping!$D28&mapping!$E28 -> محمد جمال القناطر | C28: 4013 | D28: محمد جمال | E28: القناطر | F28: لوجستيكا | G28: ابورواش | H28: سوزوكي | I28: 1397 | J28: 900 | K28: 1536 | L28: 1000
A29: =mapping!$D29&mapping!$E29&mapping!$F29&mapping!$G29&mapping!$H29 -> محمد عزمي حدائق اكتوبر لوجستيكااكتوبر هاي اس | B29: =mapping!$D29&mapping!$E29 -> محمد عزمي حدائق اكتوبر | C29: 4005 | D29: محمد عزمي | E29: حدائق اكتوبر | F29: لوجستيكا | G29: اكتوبر | H29: هاي اس | I29: 1730 | J29: 1450 | K29: 1903 | L29: 1600
A30: =mapping!$D30&mapping!$E30&mapping!$F30&mapping!$G30&mapping!$H30 -> سعيد كمال م.نصر لوجستيكااكتوبر هاي اس | B30: =mapping!$D30&mapping!$E30 -> سعيد كمال م.نصر | C30: 4008 | D30: سعيد كمال | E30: م.نصر | F30: لوجستيكا | G30: اكتوبر | H30: هاي اس | I30: 3061 | J30: 2300 | K30: 3367 | L30: 2600
A31: =mapping!$D31&mapping!$E31&mapping!$F31&mapping!$G31&mapping!$H31 -> احمد عويس اضافيالمعادي لوجستيكاابورواش إضافي | B31: =mapping!$D31&mapping!$E31 -> احمد عويس اضافيالمعادي | C31: 4012 | D31: احمد عويس اضافي | E31: المعادي | F31: لوجستيكا | G31: ابورواش | H31: إضافي | I31: 1863 | J31: 1500 | K31: 2049 | L31: 1800
A32: =mapping!$D32&mapping!$E32&mapping!$F32&mapping!$G32&mapping!$H32 -> محمد جمال إضافيالقناطر لوجستيكاابورواش إضافي | B32: =mapping!$D32&mapping!$E32 -> محمد جمال إضافيالقناطر | C32: 4014 | D32: محمد جمال إضافي | E32: القناطر | F32: لوجستيكا | G32: ابورواش | H32: إضافي | I32: 1397 | J32: 900 | K32: 1536 | L32: 1000
A33: =mapping!$D33&mapping!$E33&mapping!$F33&mapping!$G33&mapping!$H33 -> حسام سعيد إضافيإضافيلوجستيكاإضافيإضافي | B33: =mapping!$D33&mapping!$E33 -> حسام سعيد إضافيإضافي | C33: 4015 | D33: حسام سعيد إضافي | E33: إضافي | F33: لوجستيكا | G33: إضافي | H33: إضافي | K33: 1
A34: =mapping!$D34&mapping!$E34&mapping!$F34&mapping!$G34&mapping!$H34 -> محمد عزمي إضافيإضافيلوجستيكاإضافيإضافي | B34: =mapping!$D34&mapping!$E34 -> محمد عزمي إضافيإضافي | C34: 4016 | D34: محمد عزمي إضافي | E34: إضافي | F34: لوجستيكا | G34: إضافي | H34: إضافي | K34: 1
A35: =mapping!$D35&mapping!$E35&mapping!$F35&mapping!$G35&mapping!$H35 -> احمد محمود إضافيإضافيلوجستيكاإضافيإضافي | B35: =mapping!$D35&mapping!$E35 -> احمد محمود إضافيإضافي | C35: 4017 | D35: احمد محمود إضافي | E35: إضافي | F35: لوجستيكا | G35: إضافي | H35: إضافي | K35: 1
A36: =mapping!$D36&mapping!$E36&mapping!$F36&mapping!$G36&mapping!$H36 -> سامي إضافيإضافيلوجستيكاإضافيإضافي | B36: =mapping!$D36&mapping!$E36 -> سامي إضافيإضافي | C36: 4018 | D36: سامي إضافي | E36: إضافي | F36: لوجستيكا | G36: إضافي | H36: إضافي | K36: 1
A37: =mapping!$D37&mapping!$E37&mapping!$F37&mapping!$G37&mapping!$H37 -> عبدو إضافيإضافيلوجستيكاإضافيإضافي | B37: =mapping!$D37&mapping!$E37 -> عبدو إضافيإضافي | C37: 4019 | D37: عبدو إضافي | E37: إضافي | F37: لوجستيكا | G37: إضافي | H37: إضافي | K37: 1
A38: =mapping!$D38&mapping!$E38&mapping!$F38&mapping!$G38&mapping!$H38 -> احمد السيد إضافيإضافيلوجستيكاإضافيإضافي | B38: =mapping!$D38&mapping!$E38 -> احمد السيد إضافيإضافي | C38: 4020 | D38: احمد السيد إضافي | E38: إضافي | F38: لوجستيكا | G38: إضافي | H38: إضافي | K38: 1
A39: =mapping!$D39&mapping!$E39&mapping!$F39&mapping!$G39&mapping!$H39 -> محمد رضا إضافيإضافيلوجستيكاإضافيإضافي | B39: =mapping!$D39&mapping!$E39 -> محمد رضا إضافيإضافي | C39: 4022 | D39: محمد رضا إضافي | E39: إضافي | F39: لوجستيكا | G39: إضافي | H39: إضافي | K39: 1
A40: =mapping!$D40&mapping!$E40&mapping!$F40&mapping!$G40&mapping!$H40 -> إضافيإضافيلوجستيكاإضافيإضافي | B40: =mapping!$D40&mapping!$E40 -> إضافيإضافي | C40: 4021 | D40: إضافي | E40: إضافي | F40: لوجستيكا | G40: إضافي | H40: إضافي | K40: 1
...

Sheet تشغيل اليومية 
A1: ادخال | B1: ادخال | C1: ادخال | L1: ادخال | P1: ادخال | Q1: ادخال | R1: ادخال
A2: اليوم | B2: الشهر | C2: العام | D2: Column1 | E2: كود السائق | F2: اسم السائق | G2: اسم الخط | H2: اسم الشركة | I2: الفرع | J2: نوع السيارة | K2: سعر اليومية | L2: عدد الدورات | M2: سعر يومية السائق | N2: W/H 3% | O2: الاجمالي | P2: سلف | Q2: خصم | R2: اضافي | S2: الصافي المستحق للسائق | T2: ملاحظات | U2: ارباح اليومية | V2: الايراد | W2: التاريخ | X2: نوع العملية
A3: 28 | B3: 2 | C3: 2026 | D3: =F3&G3&H3&I3&J3 -> مصطفي قليوبقليوب FIRST STARTم.نصر ميكروباص صيني | E3: 1000 | F3: =VLOOKUP(E3,mapping!C:J,2,FALSE) -> مصطفي قليوب | G3: =IFERROR(VLOOKUP(F3,mapping!$D$3:$J$200,2,FALSE),0) -> قليوب | H3: =IFERROR(VLOOKUP(F3,mapping!$D$3:$J$200,3,FALSE),0) -> FIRST START | I3: =IFERROR(VLOOKUP(F3,mapping!$D$3:$J$200,4,FALSE),0) -> م.نصر | J3: =IFERROR(VLOOKUP(F3,mapping!$D$3:$J$200,5,FALSE),0) -> ميكروباص صيني | K3: =IF(W3=mapping!$N$1,IFERROR(VLOOKUP(Table4[[#This Row],[Column1]],mapping!A:L,11,FALSE),0),IFERROR(VLOOKUP(Table4[[#This Row],[Column1]],mapping!A:L,9,FALSE),0)) -> 1250 | L3: 24 | M3: =IF(W3=mapping!$N$1,IFERROR(VLOOKUP(Table4[[#This Row],[Column1]],mapping!A:L,12,FALSE),0),IFERROR(VLOOKUP(Table4[[#This Row],[Column1]],mapping!A:L,10,FALSE),0)) -> 1100 | N3: =Table4[[#This Row],[ سعر اليومية ]]*3%*Table4[[#This Row],[عدد الدورات ]] -> 900 | O3: =Table4[[#This Row],[ سعر اليومية ]]*Table4[[#This Row],[عدد الدورات ]]-N3 -> 29100 | S3: =(Table4[[#This Row],[سعر يومية السائق]]*Table4[[#This Row],[عدد الدورات ]])-SUM(Table4[[#This Row],[سلف ]:[خصم ]])+Table4[[#This Row],[اضافي ]] -> 26400 | U3: =Table4[[#This Row],[ سعر اليومية ]]*Table4[[#This Row],[عدد الدورات ]]-Table4[[#This Row],[سعر يومية السائق]]*L3 -> 3600 | V3: =U3-Table4[[#This Row],[W/H 3%]] -> 2700 | W3: =Table4[[#This Row],[اليوم]]&Table4[[#This Row],[الشهر ]]&Table4[[#This Row],[العام]] -> 2822026 | X3: ايراد
A4: 28 | B4: 2 | C4: 2026 | D4: =F4&G4&H4&I4&J4 -> سعيد الصباغ داخلي FIRST STARTالتجمع سوزوكي | E4: 1001 | F4: =VLOOKUP(E4,mapping!C:J,2,FALSE) -> سعيد الصباغ | G4: =IFERROR(VLOOKUP(F4,mapping!$D$3:$J$200,2,FALSE),0) -> داخلي | H4: =IFERROR(VLOOKUP(F4,mapping!$D$3:$J$200,3,FALSE),0) -> FIRST START | I4: =IFERROR(VLOOKUP(F4,mapping!$D$3:$J$200,4,FALSE),0) -> التجمع | J4: =IFERROR(VLOOKUP(F4,mapping!$D$3:$J$200,5,FALSE),0) -> سوزوكي | K4: =IF(W4=mapping!$N$1,IFERROR(VLOOKUP(Table4[[#This Row],[Column1]],mapping!A:L,11,FALSE),0),IFERROR(VLOOKUP(Table4[[#This Row],[Column1]],mapping!A:L,9,FALSE),0)) -> 30000 | L4: 1 | M4: =IF(W4=mapping!$N$1,IFERROR(VLOOKUP(Table4[[#This Row],[Column1]],mapping!A:L,12,FALSE),0),IFERROR(VLOOKUP(Table4[[#This Row],[Column1]],mapping!A:L,10,FALSE),0)) -> 25000 | N4: =Table4[[#This Row],[ سعر اليومية ]]*3%*Table4[[#This Row],[عدد الدورات ]] -> 900 | O4: =Table4[[#This Row],[ سعر اليومية ]]*Table4[[#This Row],[عدد الدورات ]]-N4 -> 29100 | S4: =(Table4[[#This Row],[سعر يومية السائق]]*Table4[[#This Row],[عدد الدورات ]])-SUM(Table4[[#This Row],[سلف ]:[خصم ]])+Table4[[#This Row],[اضافي ]] -> 25000 | U4: =Table4[[#This Row],[ سعر اليومية ]]*Table4[[#This Row],[عدد الدورات ]]-Table4[[#This Row],[سعر يومية السائق]]*L4 -> 5000 | V4: =U4-Table4[[#This Row],[W/H 3%]] -> 4100 | W4: =Table4[[#This Row],[اليوم]]&Table4[[#This Row],[الشهر ]]&Table4[[#This Row],[العام]] -> 2822026 | X4: ايراد
A5: 28 | B5: 2 | C5: 2026 | D5: =F5&G5&H5&I5&J5 -> عمرو برعي الجراجFLITCH AND GRAINالتجمع ميكروباص صيني | E5: 2000 | F5: =VLOOKUP(E5,mapping!C:J,2,FALSE) -> عمرو برعي | G5: =IFERROR(VLOOKUP(F5,mapping!$D$3:$J$200,2,FALSE),0) -> الجراج | H5: =IFERROR(VLOOKUP(F5,mapping!$D$3:$J$200,3,FALSE),0) -> FLITCH AND GRAIN | I5: =IFERROR(VLOOKUP(F5,mapping!$D$3:$J$200,4,FALSE),0) -> التجمع | J5: =IFERROR(VLOOKUP(F5,mapping!$D$3:$J$200,5,FALSE),0) -> ميكروباص صيني | K5: =IF(W5=mapping!$N$1,IFERROR(VLOOKUP(Table4[[#This Row],[Column1]],mapping!A:L,11,FALSE),0),IFERROR(VLOOKUP(Table4[[#This Row],[Column1]],mapping!A:L,9,FALSE),0)) -> 1150 | L5: 23 | M5: =IF(W5=mapping!$N$1,IFERROR(VLOOKUP(Table4[[#This Row],[Column1]],mapping!A:L,12,FALSE),0),IFERROR(VLOOKUP(Table4[[#This Row],[Column1]],mapping!A:L,10,FALSE),0)) -> 950 | N5: =Table4[[#This Row],[ سعر اليومية ]]*3%*Table4[[#This Row],[عدد الدورات ]] -> 793.5 | O5: =Table4[[#This Row],[ سعر اليومية ]]*Table4[[#This Row],[عدد الدورات ]]-N5 -> 25656.5 | S5: =(Table4[[#This Row],[سعر يومية السائق]]*Table4[[#This Row],[عدد الدورات ]])-SUM(Table4[[#This Row],[سلف ]:[خصم ]])+Table4[[#This Row],[اضافي ]] -> 21850 | U5: =Table4[[#This Row],[ سعر اليومية ]]*Table4[[#This Row],[عدد الدورات ]]-Table4[[#This Row],[سعر يومية السائق]]*L5 -> 4600 | V5: =U5-Table4[[#This Row],[W/H 3%]] -> 3806.5 | W5: =Table4[[#This Row],[اليوم]]&Table4[[#This Row],[الشهر ]]&Table4[[#This Row],[العام]] -> 2822026 | X5: ايراد
A6: 28 | B6: 2 | C6: 2026 | D6: =F6&G6&H6&I6&J6 -> مصطفي الف مسكنالف مسكن 3 ورديةنجمة هليوبوليسالتجمع اتوبيس 28 | E6: 3000 | F6: =VLOOKUP(E6,mapping!C:J,2,FALSE) -> مصطفي الف مسكن | G6: =IFERROR(VLOOKUP(F6,mapping!$D$3:$J$200,2,FALSE),0) -> الف مسكن 3 وردية | H6: =IFERROR(VLOOKUP(F6,mapping!$D$3:$J$200,3,FALSE),0) -> نجمة هليوبوليس | I6: =IFERROR(VLOOKUP(F6,mapping!$D$3:$J$200,4,FALSE),0) -> التجمع | J6: =IFERROR(VLOOKUP(F6,mapping!$D$3:$J$200,5,FALSE),0) -> اتوبيس 28 | K6: =IF(W6=mapping!$N$1,IFERROR(VLOOKUP(Table4[[#This Row],[Column1]],mapping!A:L,11,FALSE),0),IFERROR(VLOOKUP(Table4[[#This Row],[Column1]],mapping!A:L,9,FALSE),0)) -> 4016 | L6: 28 | M6: =IF(W6=mapping!$N$1,IFERROR(VLOOKUP(Table4[[#This Row],[Column1]],mapping!A:L,12,FALSE),0),IFERROR(VLOOKUP(Table4[[#This Row],[Column1]],mapping!A:L,10,FALSE),0)) -> 3500 | N6: =Table4[[#This Row],[ سعر اليومية ]]*3%*Table4[[#This Row],[عدد الدورات ]] -> 3373.44 | O6: =Table4[[#This Row],[ سعر اليومية ]]*Table4[[#This Row],[عدد الدورات ]]-N6 -> 109074.56 | S6: =(Table4[[#This Row],[سعر يومية السائق]]*Table4[[#This Row],[عدد الدورات ]])-SUM(Table4[[#This Row],[سلف ]:[خصم ]])+Table4[[#This Row],[اضافي ]] -> 98000 | U6: =Table4[[#This Row],[ سعر اليومية ]]*Table4[[#This Row],[عدد الدورات ]]-Table4[[#This Row],[سعر يومية السائق]]*L6 -> 14448 | V6: =U6-Table4[[#This Row],[W/H 3%]] -> 11074.56 | W6: =Table4[[#This Row],[اليوم]]&Table4[[#This Row],[الشهر ]]&Table4[[#This Row],[العام]] -> 2822026 | X6: ايراد
A7: 28 | B7: 2 | C7: 2026 | D7: =F7&G7&H7&I7&J7 -> محمد عبد المنعم قليوب 1 ورديةنجمة هليوبوليسالتجمع اتوبيس 28 | E7: 3001 | F7: =VLOOKUP(E7,mapping!C:J,2,FALSE) -> محمد عبد المنعم | G7: =IFERROR(VLOOKUP(F7,mapping!$D$3:$J$200,2,FALSE),0) -> قليوب 1 وردية | H7: =IFERROR(VLOOKUP(F7,mapping!$D$3:$J$200,3,FALSE),0) -> نجمة هليوبوليس | I7: =IFERROR(VLOOKUP(F7,mapping!$D$3:$J$200,4,FALSE),0) -> التجمع | J7: =IFERROR(VLOOKUP(F7,mapping!$D$3:$J$200,5,FALSE),0) -> اتوبيس 28 | K7: =IF(W7=mapping!$N$1,IFERROR(VLOOKUP(Table4[[#This Row],[Column1]],mapping!A:L,11,FALSE),0),IFERROR(VLOOKUP(Table4[[#This Row],[Column1]],mapping!A:L,9,FALSE),0)) -> 1786 | L7: 28 | M7: =IF(W7=mapping!$N$1,IFERROR(VLOOKUP(Table4[[#This Row],[Column1]],mapping!A:L,12,FALSE),0),IFERROR(VLOOKUP(Table4[[#This Row],[Column1]],mapping!A:L,10,FALSE),0)) -> 1800 | N7: =Table4[[#This Row],[ سعر اليومية ]]*3%*Table4[[#This Row],[عدد الدورات ]] -> 1500.24 | O7: =Table4[[#This Row],[ سعر اليومية ]]*Table4[[#This Row],[عدد الدورات ]]-N7 -> 48507.76 | S7: =(Table4[[#This Row],[سعر يومية السائق]]*Table4[[#This Row],[عدد الدورات ]])-SUM(Table4[[#This Row],[سلف ]:[خصم ]])+Table4[[#This Row],[اضافي ]] -> 50400 | U7: =Table4[[#This Row],[ سعر اليومية ]]*Table4[[#This Row],[عدد الدورات ]]-Table4[[#This Row],[سعر يومية السائق]]*L7 -> -392 | V7: =U7-Table4[[#This Row],[W/H 3%]] -> -1892.24 | W7: =Table4[[#This Row],[اليوم]]&Table4[[#This Row],[الشهر ]]&Table4[[#This Row],[العام]] -> 2822026 | X7: ايراد
A8: 28 | B8: 2 | C8: 2026 | D8: =F8&G8&H8&I8&J8 -> ممدوح كيلاني1قليوب 3 وردية نجمة هليوبوليسالتجمع اتوبيس 28 | E8: 3002 | F8: =VLOOKUP(E8,mapping!C:J,2,FALSE) -> ممدوح كيلاني1 | G8: =IFERROR(VLOOKUP(F8,mapping!$D$3:$J$200,2,FALSE),0) -> قليوب 3 وردية | H8: =IFERROR(VLOOKUP(F8,mapping!$D$3:$J$200,3,FALSE),0) -> نجمة هليوبوليس | I8: =IFERROR(VLOOKUP(F8,mapping!$D$3:$J$200,4,FALSE),0) -> التجمع | J8: =IFERROR(VLOOKUP(F8,mapping!$D$3:$J$200,5,FALSE),0) -> اتوبيس 28 | K8: =IF(W8=mapping!$N$1,IFERROR(VLOOKUP(Table4[[#This Row],[Column1]],mapping!A:L,11,FALSE),0),IFERROR(VLOOKUP(Table4[[#This Row],[Column1]],mapping!A:L,9,FALSE),0)) -> 4016 | L8: 28 | M8: =IF(W8=mapping!$N$1,IFERROR(VLOOKUP(Table4[[#This Row],[Column1]],mapping!A:L,12,FALSE),0),IFERROR(VLOOKUP(Table4[[#This Row],[Column1]],mapping!A:L,10,FALSE),0)) -> 3600 | N8: =Table4[[#This Row],[ سعر اليومية ]]*3%*Table4[[#This Row],[عدد الدورات ]] -> 3373.44 | O8: =Table4[[#This Row],[ سعر اليومية ]]*Table4[[#This Row],[عدد الدورات ]]-N8 -> 109074.56 | S8: =(Table4[[#This Row],[سعر يومية السائق]]*Table4[[#This Row],[عدد الدورات ]])-SUM(Table4[[#This Row],[سلف ]:[خصم ]])+Table4[[#This Row],[اضافي ]] -> 100800 | U8: =Table4[[#This Row],[ سعر اليومية ]]*Table4[[#This Row],[عدد الدورات ]]-Table4[[#This Row],[سعر يومية السائق]]*L8 -> 11648 | V8: =U8-Table4[[#This Row],[W/H 3%]] -> 8274.56 | W8: =Table4[[#This Row],[اليوم]]&Table4[[#This Row],[الشهر ]]&Table4[[#This Row],[العام]] -> 2822026 | X8: ايراد
A9: 28 | B9: 2 | C9: 2026 | D9: =F9&G9&H9&I9&J9 -> ممدوح كيلاني2المنيب 3وردية نجمة هليوبوليسالتجمع اتوبيس 28 | E9: 3003 | F9: =VLOOKUP(E9,mapping!C:J,2,FALSE) -> ممدوح كيلاني2 | G9: =IFERROR(VLOOKUP(F9,mapping!$D$3:$J$200,2,FALSE),0) -> المنيب 3وردية | H9: =IFERROR(VLOOKUP(F9,mapping!$D$3:$J$200,3,FALSE),0) -> نجمة هليوبوليس | I9: =IFERROR(VLOOKUP(F9,mapping!$D$3:$J$200,4,FALSE),0) -> التجمع | J9: =IFERROR(VLOOKUP(F9,mapping!$D$3:$J$200,5,FALSE),0) -> اتوبيس 28 | K9: =IF(W9=mapping!$N$1,IFERROR(VLOOKUP(Table4[[#This Row],[Column1]],mapping!A:L,11,FALSE),0),IFERROR(VLOOKUP(Table4[[#This Row],[Column1]],mapping!A:L,9,FALSE),0)) -> 4016 | L9: 28 | M9: =IF(W9=mapping!$N$1,IFERROR(VLOOKUP(Table4[[#This Row],[Column1]],mapping!A:L,12,FALSE),0),IFERROR(VLOOKUP(Table4[[#This Row],[Column1]],mapping!A:L,10,FALSE),0)) -> 3400 | N9: =Table4[[#This Row],[ سعر اليومية ]]*3%*Table4[[#This Row],[عدد الدورات ]] -> 3373.44 | O9: =Table4[[#This Row],[ سعر اليومية ]]*Table4[[#This Row],[عدد الدورات ]]-N9 -> 109074.56 | S9: =(Table4[[#This Row],[سعر يومية السائق]]*Table4[[#This Row],[عدد الدورات ]])-SUM(Table4[[#This Row],[سلف ]:[خصم ]])+Table4[[#This Row],[اضافي ]] -> 95200 | U9: =Table4[[#This Row],[ سعر اليومية ]]*Table4[[#This Row],[عدد الدورات ]]-Table4[[#This Row],[سعر يومية السائق]]*L9 -> 17248 | V9: =U9-Table4[[#This Row],[W/H 3%]] -> 13874.56 | W9: =Table4[[#This Row],[اليوم]]&Table4[[#This Row],[الشهر ]]&Table4[[#This Row],[العام]] -> 2822026 | X9: ايراد
A10: 28 | B10: 2 | C10: 2026 | D10: =F10&G10&H10&I10&J10 -> رجب سلامة 1المرج لوجستيكااكتوبر هاي اس | E10: 4000 | F10: =VLOOKUP(E10,mapping!C:J,2,FALSE) -> رجب سلامة 1 | G10: =IFERROR(VLOOKUP(F10,mapping!$D$3:$J$200,2,FALSE),0) -> المرج | H10: =IFERROR(VLOOKUP(F10,mapping!$D$3:$J$200,3,FALSE),0) -> لوجستيكا | I10: =IFERROR(VLOOKUP(F10,mapping!$D$3:$J$200,4,FALSE),0) -> اكتوبر | J10: =IFERROR(VLOOKUP(F10,mapping!$D$3:$J$200,5,FALSE),0) -> هاي اس | K10: =IF(W10=mapping!$N$1,IFERROR(VLOOKUP(Table4[[#This Row],[Column1]],mapping!A:L,11,FALSE),0),IFERROR(VLOOKUP(Table4[[#This Row],[Column1]],mapping!A:L,9,FALSE),0)) -> 1996 | L10: 24 | M10: =IF(W10=mapping!$N$1,IFERROR(VLOOKUP(Table4[[#This Row],[Column1]],mapping!A:L,12,FALSE),0),IFERROR(VLOOKUP(Table4[[#This Row],[Column1]],mapping!A:L,10,FALSE),0)) -> 1800 | N10: =Table4[[#This Row],[ سعر اليومية ]]*3%*Table4[[#This Row],[عدد الدورات ]] -> 1437.12 | O10: =Table4[[#This Row],[ سعر اليومية ]]*Table4[[#This Row],[عدد الدورات ]]-N10 -> 46466.88 | S10: =(Table4[[#This Row],[سعر يومية السائق]]*Table4[[#This Row],[عدد الدورات ]])-SUM(Table4[[#This Row],[سلف ]:[خصم ]])+Table4[[#This Row],[اضافي ]] -> 43200 | U10: =Table4[[#This Row],[ سعر اليومية ]]*Table4[[#This Row],[عدد الدورات ]]-Table4[[#This Row],[سعر يومية السائق]]*L10 -> 4704 | V10: =U10-Table4[[#This Row],[W/H 3%]] -> 3266.88 | W10: =Table4[[#This Row],[اليوم]]&Table4[[#This Row],[الشهر ]]&Table4[[#This Row],[العام]] -> 2822026 | X10: ايراد
A11: 28 | B11: 2 | C11: 2026 | D11: =F11&G11&H11&I11&J11 -> احمد السيدالمنيب 3وردية لوجستيكااكتوبر هاي اس | E11: 4001 | F11: =VLOOKUP(E11,mapping!C:J,2,FALSE) -> احمد السيد | G11: =IFERROR(VLOOKUP(F11,mapping!$D$3:$J$200,2,FALSE),0) -> المنيب 3وردية | H11: =IFERROR(VLOOKUP(F11,mapping!$D$3:$J$200,3,FALSE),0) -> لوجستيكا | I11: =IFERROR(VLOOKUP(F11,mapping!$D$3:$J$200,4,FALSE),0) -> اكتوبر | J11: =IFERROR(VLOOKUP(F11,mapping!$D$3:$J$200,5,FALSE),0) -> هاي اس | K11: =IF(W11=mapping!$N$1,IFERROR(VLOOKUP(Table4[[#This Row],[Column1]],mapping!A:L,11,FALSE),0),IFERROR(VLOOKUP(Table4[[#This Row],[Column1]],mapping!A:L,9,FALSE),0)) -> 4392 | L11: 24 | M11: =IF(W11=mapping!$N$1,IFERROR(VLOOKUP(Table4[[#This Row],[Column1]],mapping!A:L,12,FALSE),0),IFERROR(VLOOKUP(Table4[[#This Row],[Column1]],mapping!A:L,10,FALSE),0)) -> 3750 | N11: =Table4[[#This Row],[ سعر اليومية ]]*3%*Table4[[#This Row],[عدد الدورات ]] -> 3162.24 | O11: =Table4[[#This Row],[ سعر اليومية ]]*Table4[[#This Row],[عدد الدورات ]]-N11 -> 102245.76 | S11: =(Table4[[#This Row],[سعر يومية السائق]]*Table4[[#This Row],[عدد الدورات ]])-SUM(Table4[[#This Row],[سلف ]:[خصم ]])+Table4[[#This Row],[اضافي ]] -> 90000 | U11: =Table4[[#This Row],[ سعر اليومية ]]*Table4[[#This Row],[عدد الدورات ]]-Table4[[#This Row],[سعر يومية السائق]]*L11 -> 15408 | V11: =U11-Table4[[#This Row],[W/H 3%]] -> 12245.76 | W11: =Table4[[#This Row],[اليوم]]&Table4[[#This Row],[الشهر ]]&Table4[[#This Row],[العام]] -> 2822026 | X11: ايراد
A12: 28 | B12: 2 | C12: 2026 | D12: =F12&G12&H12&I12&J12 -> حسام سعيد1القناطر 3 ورديةلوجستيكااكتوبر هاي اس | E12: 4002 | F12: =VLOOKUP(E12,mapping!C:J,2,FALSE) -> حسام سعيد1 | G12: =IFERROR(VLOOKUP(F12,mapping!$D$3:$J$200,2,FALSE),0) -> القناطر 3 وردية | H12: =IFERROR(VLOOKUP(F12,mapping!$D$3:$J$200,3,FALSE),0) -> لوجستيكا | I12: =IFERROR(VLOOKUP(F12,mapping!$D$3:$J$200,4,FALSE),0) -> اكتوبر | J12: =IFERROR(VLOOKUP(F12,mapping!$D$3:$J$200,5,FALSE),0) -> هاي اس | K12: =IF(W12=mapping!$N$1,IFERROR(VLOOKUP(Table4[[#This Row],[Column1]],mapping!A:L,11,FALSE),0),IFERROR(VLOOKUP(Table4[[#This Row],[Column1]],mapping!A:L,9,FALSE),0)) -> 3992 | L12: 24 | M12: =IF(W12=mapping!$N$1,IFERROR(VLOOKUP(Table4[[#This Row],[Column1]],mapping!A:L,12,FALSE),0),IFERROR(VLOOKUP(Table4[[#This Row],[Column1]],mapping!A:L,10,FALSE),0)) -> 3100 | N12: =Table4[[#This Row],[ سعر اليومية ]]*3%*Table4[[#This Row],[عدد الدورات ]] -> 2874.24 | O12: =Table4[[#This Row],[ سعر اليومية ]]*Table4[[#This Row],[عدد الدورات ]]-N12 -> 92933.76 | S12: =(Table4[[#This Row],[سعر يومية السائق]]*Table4[[#This Row],[عدد الدورات ]])-SUM(Table4[[#This Row],[سلف ]:[خصم ]])+Table4[[#This Row],[اضافي ]] -> 74400 | U12: =Table4[[#This Row],[ سعر اليومية ]]*Table4[[#This Row],[عدد الدورات ]]-Table4[[#This Row],[سعر يومية السائق]]*L12 -> 21408 | V12: =U12-Table4[[#This Row],[W/H 3%]] -> 18533.76 | W12: =Table4[[#This Row],[اليوم]]&Table4[[#This Row],[الشهر ]]&Table4[[#This Row],[العام]] -> 2822026 | X12: ايراد
A13: 28 | B13: 2 | C13: 2026 | D13: =F13&G13&H13&I13&J13 -> حسام سعيد 2نكلا انصرافلوجستيكااكتوبر هاي اس | E13: 4003 | F13: =VLOOKUP(E13,mapping!C:J,2,FALSE) -> حسام سعيد 2 | G13: =IFERROR(VLOOKUP(F13,mapping!$D$3:$J$200,2,FALSE),0) -> نكلا انصراف | H13: =IFERROR(VLOOKUP(F13,mapping!$D$3:$J$200,3,FALSE),0) -> لوجستيكا | I13: =IFERROR(VLOOKUP(F13,mapping!$D$3:$J$200,4,FALSE),0) -> اكتوبر | J13: =IFERROR(VLOOKUP(F13,mapping!$D$3:$J$200,5,FALSE),0) -> هاي اس | K13: =IF(W13=mapping!$N$1,IFERROR(VLOOKUP(Table4[[#This Row],[Column1]],mapping!A:L,11,FALSE),0),IFERROR(VLOOKUP(Table4[[#This Row],[Column1]],mapping!A:L,9,FALSE),0)) -> 931.5 | L13: 24 | M13: =IF(W13=mapping!$N$1,IFERROR(VLOOKUP(Table4[[#This Row],[Column1]],mapping!A:L,12,FALSE),0),IFERROR(VLOOKUP(Table4[[#This Row],[Column1]],mapping!A:L,10,FALSE),0)) -> 800 | N13: =Table4[[#This Row],[ سعر اليومية ]]*3%*Table4[[#This Row],[عدد الدورات ]] -> 670.68 | O13: =Table4[[#This Row],[ سعر اليومية ]]*Table4[[#This Row],[عدد الدورات ]]-N13 -> 21685.32 | S13: =(Table4[[#This Row],[سعر يومية السائق]]*Table4[[#This Row],[عدد الدورات ]])-SUM(Table4[[#This Row],[سلف ]:[خصم ]])+Table4[[#This Row],[اضافي ]] -> 19200 | U13: =Table4[[#This Row],[ سعر اليومية ]]*Table4[[#This Row],[عدد الدورات ]]-Table4[[#This Row],[سعر يومية السائق]]*L13 -> 3156 | V13: =U13-Table4[[#This Row],[W/H 3%]] -> 2485.32 | W13: =Table4[[#This Row],[اليوم]]&Table4[[#This Row],[الشهر ]]&Table4[[#This Row],[العام]] -> 2822026 | X13: ايراد
A14: 28 | B14: 2 | C14: 2026 | D14: =F14&G14&H14&I14&J14 -> رجب سلامة 2 نكلا حضورلوجستيكااكتوبر هاي اس | E14: 4004 | F14: =VLOOKUP(E14,mapping!C:J,2,FALSE) -> رجب سلامة 2 | G14: =IFERROR(VLOOKUP(F14,mapping!$D$3:$J$200,2,FALSE),0) -> نكلا حضور | H14: =IFERROR(VLOOKUP(F14,mapping!$D$3:$J$200,3,FALSE),0) -> لوجستيكا | I14: =IFERROR(VLOOKUP(F14,mapping!$D$3:$J$200,4,FALSE),0) -> اكتوبر | J14: =IFERROR(VLOOKUP(F14,mapping!$D$3:$J$200,5,FALSE),0) -> هاي اس | K14: =IF(W14=mapping!$N$1,IFERROR(VLOOKUP(Table4[[#This Row],[Column1]],mapping!A:L,11,FALSE),0),IFERROR(VLOOKUP(Table4[[#This Row],[Column1]],mapping!A:L,9,FALSE),0)) -> 931.5 | L14: 24 | M14: =IF(W14=mapping!$N$1,IFERROR(VLOOKUP(Table4[[#This Row],[Column1]],mapping!A:L,12,FALSE),0),IFERROR(VLOOKUP(Table4[[#This Row],[Column1]],mapping!A:L,10,FALSE),0)) -> 875 | N14: =Table4[[#This Row],[ سعر اليومية ]]*3%*Table4[[#This Row],[عدد الدورات ]] -> 670.68 | O14: =Table4[[#This Row],[ سعر اليومية ]]*Table4[[#This Row],[عدد الدورات ]]-N14 -> 21685.32 | S14: =(Table4[[#This Row],[سعر يومية السائق]]*Table4[[#This Row],[عدد الدورات ]])-SUM(Table4[[#This Row],[سلف ]:[خصم ]])+Table4[[#This Row],[اضافي ]] -> 21000 | U14: =Table4[[#This Row],[ سعر اليومية ]]*Table4[[#This Row],[عدد الدورات ]]-Table4[[#This Row],[سعر يومية السائق]]*L14 -> 1356 | V14: =U14-Table4[[#This Row],[W/H 3%]] -> 685.32 | W14: =Table4[[#This Row],[اليوم]]&Table4[[#This Row],[الشهر ]]&Table4[[#This Row],[العام]] -> 2822026 | X14: ايراد
... A39: 28 | B39: 2 | C39: 2026 | D39: =F39&G39&H39&I39&J39 -> مصطفي رشدي5صقر 2 ورديةسعوديالقطاميةاتوبيس 28 | E39: 5014 | F39: =VLOOKUP(E39,mapping!C:J,2,FALSE) -> مصطفي رشدي5 | G39: =IFERROR(VLOOKUP(F39,mapping!$D$3:$J$200,2,FALSE),0) -> صقر 2 وردية | H39: =IFERROR(VLOOKUP(F39,mapping!$D$3:$J$200,3,FALSE),0) -> سعودي | I39: =IFERROR(VLOOKUP(F39,mapping!$D$3:$J$200,4,FALSE),0) -> القطامية | J39: =IFERROR(VLOOKUP(F39,mapping!$D$3:$J$200,5,FALSE),0) -> اتوبيس 28 | K39: =IF(W39=mapping!$N$1,IFERROR(VLOOKUP(Table4[[#This Row],[Column1]],mapping!A:L,11,FALSE),0),IFERROR(VLOOKUP(Table4[[#This Row],[Column1]],mapping!A:L,9,FALSE),0)) -> 1927 | L39: 28 | M39: =IF(W39=mapping!$N$1,IFERROR(VLOOKUP(Table4[[#This Row],[Column1]],mapping!A:L,12,FALSE),0),IFERROR(VLOOKUP(Table4[[#This Row],[Column1]],mapping!A:L,10,FALSE),0)) -> 1660 | N39: =Table4[[#This Row],[ سعر اليومية ]]*3%*Table4[[#This Row],[عدد الدورات ]] -> 1618.68 | O39: =Table4[[#This Row],[ سعر اليومية ]]*Table4[[#This Row],[عدد الدورات ]]-N39 -> 52337.32 | S39: =(Table4[[#This Row],[سعر يومية السائق]]*Table4[[#This Row],[عدد الدورات ]])-SUM(Table4[[#This Row],[سلف ]:[خصم ]])+Table4[[#This Row],[اضافي ]] -> 46480 | U39: =Table4[[#This Row],[ سعر اليومية ]]*Table4[[#This Row],[عدد الدورات ]]-Table4[[#This Row],[سعر يومية السائق]]*L39 -> 7476 | V39: =U39-Table4[[#This Row],[W/H 3%]] -> 5857.32 | W39: =Table4[[#This Row],[اليوم]]&Table4[[#This Row],[الشهر ]]&Table4[[#This Row],[العام]] -> 2822026 | X39: ايراد
A40: 28 | B40: 2 | C40: 2026 | D40: =F40&G40&H40&I40&J40 -> كرم ترك 1قليوب 2 ورديةسعوديالقطاميةاتوبيس 28 | E40: 5015 | F40: =VLOOKUP(E40,mapping!C:J,2,FALSE) -> كرم ترك 1 | G40: =IFERROR(VLOOKUP(F40,mapping!$D$3:$J$200,2,FALSE),0) -> قليوب 2 وردية | H40: =IFERROR(VLOOKUP(F40,mapping!$D$3:$J$200,3,FALSE),0) -> سعودي | I40: =IFERROR(VLOOKUP(F40,mapping!$D$3:$J$200,4,FALSE),0) -> القطامية | J40: =IFERROR(VLOOKUP(F40,mapping!$D$3:$J$200,5,FALSE),0) -> اتوبيس 28 | K40: =IFERROR(VLOOKUP(Table4[[#This Row],[Column1]],mapping!A:J,9,FALSE),0) -> 3599 | L40: 28 | M40: =IF(W40=mapping!$N$1,IFERROR(VLOOKUP(Table4[[#This Row],[Column1]],mapping!A:L,12,FALSE),0),IFERROR(VLOOKUP(Table4[[#This Row],[Column1]],mapping!A:L,10,FALSE),0)) -> 3800 | N40: =Table4[[#This Row],[ سعر اليومية ]]*3%*Table4[[#This Row],[عدد الدورات ]] -> 3023.16 | O40: =Table4[[#This Row],[ سعر اليومية ]]*Table4[[#This Row],[عدد الدورات ]]-N40 -> 97748.84 | S40: =(Table4[[#This Row],[سعر يومية السائق]]*Table4[[#This Row],[عدد الدورات ]])-SUM(Table4[[#This Row],[سلف ]:[خصم ]])+Table4[[#This Row],[اضافي ]] -> 106400 | U40: =Table4[[#This Row],[ سعر اليومية ]]*Table4[[#This Row],[عدد الدورات ]]-Table4[[#This Row],[سعر يومية السائق]]*L40 -> -5628 | V40: =U40-Table4[[#This Row],[W/H 3%]] -> -8651.16 | X40: ايراد
A41: 28 | B41: 2 | C41: 2026 | D41: =F41&G41&H41&I41&J41 -> محمد خطاب المنيب 2 ورديةسعوديالقطاميةاتوبيس 28 | E41: 5016 | F41: =VLOOKUP(E41,mapping!C:J,2,FALSE) -> محمد خطاب | G41: =IFERROR(VLOOKUP(F41,mapping!$D$3:$J$200,2,FALSE),0) -> المنيب 2 وردية | H41: =IFERROR(VLOOKUP(F41,mapping!$D$3:$J$200,3,FALSE),0) -> سعودي | I41: =IFERROR(VLOOKUP(F41,mapping!$D$3:$J$200,4,FALSE),0) -> القطامية | J41: =IFERROR(VLOOKUP(F41,mapping!$D$3:$J$200,5,FALSE),0) -> اتوبيس 28 | K41: =IFERROR(VLOOKUP(Table4[[#This Row],[Column1]],mapping!A:J,9,FALSE),0) -> 3587 | L41: 28 | M41: =IF(W41=mapping!$N$1,IFERROR(VLOOKUP(Table4[[#This Row],[Column1]],mapping!A:L,12,FALSE),0),IFERROR(VLOOKUP(Table4[[#This Row],[Column1]],mapping!A:L,10,FALSE),0)) -> 3210 | N41: =Table4[[#This Row],[ سعر اليومية ]]*3%*Table4[[#This Row],[عدد الدورات ]] -> 3013.08 | O41: =Table4[[#This Row],[ سعر اليومية ]]*Table4[[#This Row],[عدد الدورات ]]-N41 -> 97422.92 | S41: =(Table4[[#This Row],[سعر يومية السائق]]*Table4[[#This Row],[عدد الدورات ]])-SUM(Table4[[#This Row],[سلف ]:[خصم ]])+Table4[[#This Row],[اضافي ]] -> 89880 | U41: =Table4[[#This Row],[ سعر اليومية ]]*Table4[[#This Row],[عدد الدورات ]]-Table4[[#This Row],[سعر يومية السائق]]*L41 -> 10556 | V41: =U41-Table4[[#This Row],[W/H 3%]] -> 7542.92 | X41: ايراد
A42: 28 | B42: 2 | C42: 2026 | D42: =F42&G42&H42&I42&J42 -> كرم ترك 2قليوب 2 ورديةسعوديمدينتي اتوبيس 28 | E42: 5017 | F42: =VLOOKUP(E42,mapping!C:J,2,FALSE) -> كرم ترك 2 | G42: =IFERROR(VLOOKUP(F42,mapping!$D$3:$J$200,2,FALSE),0) -> قليوب 2 وردية | H42: =IFERROR(VLOOKUP(F42,mapping!$D$3:$J$200,3,FALSE),0) -> سعودي | I42: =IFERROR(VLOOKUP(F42,mapping!$D$3:$J$200,4,FALSE),0) -> مدينتي | J42: =IFERROR(VLOOKUP(F42,mapping!$D$3:$J$200,5,FALSE),0) -> اتوبيس 28 | K42: =IFERROR(VLOOKUP(Table4[[#This Row],[Column1]],mapping!A:J,9,FALSE),0) -> 4213 | L42: 28 | M42: =IF(W42=mapping!$N$1,IFERROR(VLOOKUP(Table4[[#This Row],[Column1]],mapping!A:L,12,FALSE),0),IFERROR(VLOOKUP(Table4[[#This Row],[Column1]],mapping!A:L,10,FALSE),0)) -> 3850 | N42: =Table4[[#This Row],[ سعر اليومية ]]*3%*Table4[[#This Row],[عدد الدورات ]] -> 3538.92 | O42: =Table4[[#This Row],[ سعر اليومية ]]*Table4[[#This Row],[عدد الدورات ]]-N42 -> 114425.08 | S42: =(Table4[[#This Row],[سعر يومية السائق]]*Table4[[#This Row],[عدد الدورات ]])-SUM(Table4[[#This Row],[سلف ]:[خصم ]])+Table4[[#This Row],[اضافي ]] -> 107800 | U42: =Table4[[#This Row],[ سعر اليومية ]]*Table4[[#This Row],[عدد الدورات ]]-Table4[[#This Row],[سعر يومية السائق]]*L42 -> 10164 | V42: =U42-Table4[[#This Row],[W/H 3%]] -> 6625.08 | X42: ايراد
A43: 28 | B43: 2 | C43: 2026 | D43: =F43&G43&H43&I43&J43 -> كرم ترك 3قليوب 1 ورديةسعوديمدينتي اتوبيس 28 | E43: 5018 | F43: =VLOOKUP(E43,mapping!C:J,2,FALSE) -> كرم ترك 3 | G43: =IFERROR(VLOOKUP(F43,mapping!$D$3:$J$200,2,FALSE),0) -> قليوب 1 وردية | H43: =IFERROR(VLOOKUP(F43,mapping!$D$3:$J$200,3,FALSE),0) -> سعودي | I43: =IFERROR(VLOOKUP(F43,mapping!$D$3:$J$200,4,FALSE),0) -> مدينتي | J43: =IFERROR(VLOOKUP(F43,mapping!$D$3:$J$200,5,FALSE),0) -> اتوبيس 28 | K43: =IFERROR(VLOOKUP(Table4[[#This Row],[Column1]],mapping!A:J,9,FALSE),0) -> 4213 | L43: 28 | M43: =IF(W43=mapping!$N$1,IFERROR(VLOOKUP(Table4[[#This Row],[Column1]],mapping!A:L,12,FALSE),0),IFERROR(VLOOKUP(Table4[[#This Row],[Column1]],mapping!A:L,10,FALSE),0)) -> 3700 | N43: =Table4[[#This Row],[ سعر اليومية ]]*3%*Table4[[#This Row],[عدد الدورات ]] -> 3538.92 | O43: =Table4[[#This Row],[ سعر اليومية ]]*Table4[[#This Row],[عدد الدورات ]]-N43 -> 114425.08 | S43: =(Table4[[#This Row],[سعر يومية السائق]]*Table4[[#This Row],[عدد الدورات ]])-SUM(Table4[[#This Row],[سلف ]:[خصم ]])+Table4[[#This Row],[اضافي ]] -> 103600 | U43: =Table4[[#This Row],[ سعر اليومية ]]*Table4[[#This Row],[عدد الدورات ]]-Table4[[#This Row],[سعر يومية السائق]]*L43 -> 14364 | V43: =U43-Table4[[#This Row],[W/H 3%]] -> 10825.08 | X43: ايراد
A44: 28 | B44: 2 | C44: 2026 | D44: =F44&G44&H44&I44&J44 -> كرم ترك 4عدلي منصور شفتسعوديمدينتي اتوبيس 28 | E44: 5019 | F44: =VLOOKUP(E44,mapping!C:J,2,FALSE) -> كرم ترك 4 | G44: =IFERROR(VLOOKUP(F44,mapping!$D$3:$J$200,2,FALSE),0) -> عدلي منصور شفت | H44: =IFERROR(VLOOKUP(F44,mapping!$D$3:$J$200,3,FALSE),0) -> سعودي | I44: =IFERROR(VLOOKUP(F44,mapping!$D$3:$J$200,4,FALSE),0) -> مدينتي | J44: =IFERROR(VLOOKUP(F44,mapping!$D$3:$J$200,5,FALSE),0) -> اتوبيس 28 | K44: =IFERROR(VLOOKUP(Table4[[#This Row],[Column1]],mapping!A:J,9,FALSE),0) -> 674 | L44: 18 | M44: =IF(W44=mapping!$N$1,IFERROR(VLOOKUP(Table4[[#This Row],[Column1]],mapping!A:L,12,FALSE),0),IFERROR(VLOOKUP(Table4[[#This Row],[Column1]],mapping!A:L,10,FALSE),0)) -> 500 | N44: =Table4[[#This Row],[ سعر اليومية ]]*3%*Table4[[#This Row],[عدد الدورات ]] -> 363.96 | O44: =Table4[[#This Row],[ سعر اليومية ]]*Table4[[#This Row],[عدد الدورات ]]-N44 -> 11768.04 | S44: =(Table4[[#This Row],[سعر يومية السائق]]*Table4[[#This Row],[عدد الدورات ]])-SUM(Table4[[#This Row],[سلف ]:[خصم ]])+Table4[[#This Row],[اضافي ]] -> 9000 | U44: =Table4[[#This Row],[ سعر اليومية ]]*Table4[[#This Row],[عدد الدورات ]]-Table4[[#This Row],[سعر يومية السائق]]*L44 -> 3132 | V44: =U44-Table4[[#This Row],[W/H 3%]] -> 2768.04 | X44: ايراد
A45: 28 | B45: 2 | C45: 2026 | D45: =F45&G45&H45&I45&J45 -> عماد النجار 4قليوب بيتوينسعوديمدينتي اتوبيس 28 | E45: 5020 | F45: =VLOOKUP(E45,mapping!C:J,2,FALSE) -> عماد النجار 4 | G45: =IFERROR(VLOOKUP(F45,mapping!$D$3:$J$200,2,FALSE),0) -> قليوب بيتوين | H45: =IFERROR(VLOOKUP(F45,mapping!$D$3:$J$200,3,FALSE),0) -> سعودي | I45: =IFERROR(VLOOKUP(F45,mapping!$D$3:$J$200,4,FALSE),0) -> مدينتي | J45: =IFERROR(VLOOKUP(F45,mapping!$D$3:$J$200,5,FALSE),0) -> اتوبيس 28 | K45: =IFERROR(VLOOKUP(Table4[[#This Row],[Column1]],mapping!A:J,9,FALSE),0) -> 1348 | L45: 28 | M45: =IF(W45=mapping!$N$1,IFERROR(VLOOKUP(Table4[[#This Row],[Column1]],mapping!A:L,12,FALSE),0),IFERROR(VLOOKUP(Table4[[#This Row],[Column1]],mapping!A:L,10,FALSE),0)) -> 1300 | N45: =Table4[[#This Row],[ سعر اليومية ]]*3%*Table4[[#This Row],[عدد الدورات ]] -> 1132.32 | O45: =Table4[[#This Row],[ سعر اليومية ]]*Table4[[#This Row],[عدد الدورات ]]-N45 -> 36611.68 | S45: =(Table4[[#This Row],[سعر يومية السائق]]*Table4[[#This Row],[عدد الدورات ]])-SUM(Table4[[#This Row],[سلف ]:[خصم ]])+Table4[[#This Row],[اضافي ]] -> 36400 | U45: =Table4[[#This Row],[ سعر اليومية ]]*Table4[[#This Row],[عدد الدورات ]]-Table4[[#This Row],[سعر يومية السائق]]*L45 -> 1344 | V45: =U45-Table4[[#This Row],[W/H 3%]] -> 211.68 | X45: ايراد
A46: 28 | B46: 2 | C46: 2026 | D46: =F46&G46&H46&I46&J46 -> ممدوح كيلاني6المنيب 1 وردية سعوديمدينتي ميكروباص صيني | E46: 5021 | F46: =VLOOKUP(E46,mapping!C:J,2,FALSE) -> ممدوح كيلاني6 | G46: =IFERROR(VLOOKUP(F46,mapping!$D$3:$J$200,2,FALSE),0) -> المنيب 1 وردية | H46: =IFERROR(VLOOKUP(F46,mapping!$D$3:$J$200,3,FALSE),0) -> سعودي | I46: =IFERROR(VLOOKUP(F46,mapping!$D$3:$J$200,4,FALSE),0) -> مدينتي | J46: =IFERROR(VLOOKUP(F46,mapping!$D$3:$J$200,5,FALSE),0) -> ميكروباص صيني | K46: =IFERROR(VLOOKUP(Table4[[#This Row],[Column1]],mapping!A:J,9,FALSE),0) -> 1348 | L46: 28 | M46: =IF(W46=mapping!$N$1,IFERROR(VLOOKUP(Table4[[#This Row],[Column1]],mapping!A:L,12,FALSE),0),IFERROR(VLOOKUP(Table4[[#This Row],[Column1]],mapping!A:L,10,FALSE),0)) -> 1200 | N46: =Table4[[#This Row],[ سعر اليومية ]]*3%*Table4[[#This Row],[عدد الدورات ]] -> 1132.32 | O46: =Table4[[#This Row],[ سعر اليومية ]]*Table4[[#This Row],[عدد الدورات ]]-N46 -> 36611.68 | S46: =(Table4[[#This Row],[سعر يومية السائق]]*Table4[[#This Row],[عدد الدورات ]])-SUM(Table4[[#This Row],[سلف ]:[خصم ]])+Table4[[#This Row],[اضافي ]] -> 33600 | U46: =Table4[[#This Row],[ سعر اليومية ]]*Table4[[#This Row],[عدد الدورات ]]-Table4[[#This Row],[سعر يومية السائق]]*L46 -> 4144 | V46: =U46-Table4[[#This Row],[W/H 3%]] -> 3011.68 | X46: ايراد
